<?xml version="1.0"?>

<robot name="my_robot" xmlns:xacro="http://www.ros.org/wiki/xacro">

<xacro:include filename="$(find my_robot)/urdf/my_robot.gazebo" />

  <!--Links-->
  <link name="robot_footprint"></link>

  <joint name="robot_footprint_joint" type="fixed">
    <origin xyz="0 0 0" rpy="0 0 0" />
    <parent link="robot_footprint" />
    <child link="chassis" />
  </joint>

  <link name="chassis">
    <pose>0 0 0.1 0 0 0</pose>
    <inertial>
      <mass value="5.0" />
      <origin xyz="0 0 0" rpy="0 0 0" />
      <inertia
        ixx="0.1" ixy="0" ixz="0"
        iyy="0.1" iyz="0"
        izz="0.1" />
    </inertial>
    <collision name="box_collision">
      <origin xyz="0 0 0.05" rpy="0 0 0" />
      <geometry>
        <box size=".4 .2 .1" />
      </geometry>
    </collision>
    <visual name="box_visual">
      <origin xyz="0 0 0.05" rpy="0 0 0" />
      <geometry>
        <box size=".4 .2 .1" />
      </geometry>
    </visual>

    <collision name="cylinder_colllision">
      <origin xyz="0.075 0 0.125" rpy="0 0 0" />
      <geometry>
        <cylinder radius=".15" length=".05" />
      </geometry>
    </collision>

    <visual name="cylinder_visual">
      <origin xyz="0.075 0 0.125" rpy="0 0 0" />
      <geometry>
        <cylinder radius=".15" length=".05" />
      </geometry>
    </visual>
    
  </link>  

  <link name="front_wheel_left">

    <inertial>
      <mass value="1.0" />
      <origin xyz="0 0.01 0" rpy="0 1.5707 1.5707" />
      <inertia
        ixx="0.1" ixy="0" ixz="0"
        iyy="0.1" iyz="0"
        izz="0.1" />
    </inertial>

    <collision name="front_wheel_left_collision">
      <origin xyz="0 0.01 0" rpy="0 1.5707 1.5707" />
      <geometry>
        <cylinder radius="0.05" length="0.02" />
      </geometry>
    </collision>

    <visual name="front_wheel_left_visual">
      <origin xyz="0 0.01 0" rpy="0 1.5707 1.5707" />
      <geometry>
        <cylinder radius="0.05" length="0.02" />
      </geometry>
    </visual>

  </link>
  
  <link name="front_wheel_right">

    <inertial>
      <mass value="1.0" />
      <origin xyz="0 -0.01 0" rpy="0 1.5707 1.5707" />
      <inertia
        ixx="0.1" ixy="0" ixz="0"
        iyy="0.1" iyz="0"
        izz="0.1" />
    </inertial>

    <collision name="front_wheel_right_collision">
      <origin xyz="0 -0.01 0" rpy="0 1.5707 1.5707" />
      <geometry>
        <cylinder radius="0.05" length="0.02" />
      </geometry>
    </collision>

    <visual name="front_wheel_right_visual">
      <origin xyz="0 -0.01 0" rpy="0 1.5707 1.5707" />
      <geometry>
        <cylinder radius="0.05" length="0.02" />
      </geometry>
    </visual>

  </link>

  <link name="rear_wheel_left">

    <inertial>
      <mass value="1.0" />
      <origin xyz="0 0.01 0" rpy="0 1.5707 1.5707" />
      <inertia
        ixx="0.1" ixy="0" ixz="0"
        iyy="0.1" iyz="0"
        izz="0.1" />
    </inertial>

    <collision name="rear_wheel_left_collision">
      <origin xyz="0 0.01 0" rpy="0 1.5707 1.5707" />
      <geometry>
        <cylinder radius="0.05" length="0.02" />
      </geometry>
    </collision>

    <visual name="rear_wheel_left_visual">
      <origin xyz="0 0.01 0" rpy="0 1.5707 1.5707" />
      <geometry>
        <cylinder radius="0.05" length="0.02" />
      </geometry>
    </visual>

  </link>

  <link name="rear_wheel_right">

    <inertial>
      <mass value="1.0" />
      <origin xyz="0 -0.01 0" rpy="0 1.5707 1.5707" />
      <inertia
        ixx="0.1" ixy="0" ixz="0"
        iyy="0.1" iyz="0"
        izz="0.1" />
    </inertial>

    <collision name="rear_wheel_right_collision">
      <origin xyz="0 -0.01 0" rpy="0 1.5707 1.5707" />
      <geometry>
        <cylinder radius="0.05" length="0.02" />
      </geometry>
    </collision>

    <visual name="rear_wheel_right_visual">
      <origin xyz="0 -0.01 0" rpy="0 1.5707 1.5707" />
      <geometry>
        <cylinder radius="0.05" length="0.02" />
      </geometry>
    </visual>

  </link>

  <link name="camera">
    
    <box_inertia m="0.1" x="0.05" y="0.05" z="0.05" />
   <inertial>
      <mass value="0.1"/>
      <inertia 
	ixx="1e-6" ixy="0" ixz="0"
        iyy="1e-6" iyz="0"
        izz="1e-6" />
    </inertial>    

    <collision name="camera_collision">
      <origin xyz="0 0 0" rpy="0 0 0" />
      <geometry>
        <box size="0.05 0.05 0.05" />
      </geometry>
    </collision>

    <visual name="camera_visual">
      <origin xyz="0 0 0" rpy="0 0 0" />
      <geometry>
        <box size="0.05 0.05 0.05" />
      </geometry>
    </visual>

  </link>

  <link name="hokuyo">

    <inertial>
      <mass value="1e-5" />
      <inertia
        ixx="1e-6" ixy="0" ixz="0"
        iyy="1e-6" iyz="0"
        izz="1e-6"
      />
    </inertial>

    <collision name="hokuyo_collision">
      <origin xyz="0 0 0" rpy="0 0 0" />
      <geometry>
        <box size="0.1 0.1 0.1" />
      </geometry>
    </collision>

    <visual name="hokuyo_visual">
      <origin xyz="0 0 0" rpy="0 0 0" />
      <geometry>
        <mesh filename="package://my_robot/meshes/hokuyo.dae" />
      </geometry>
    </visual>

  </link>

  <!--Colors-->
  <gazebo reference="chassis">
    <material>Gazebo/Blue</material>
  </gazebo>
  
  <gazebo reference="camera">
    <material>Gazebo/Red</material>
  </gazebo>

  <gazebo reference="front_wheel_right">
    <material>Gazebo/Black</material>
  </gazebo>
 
  <gazebo reference="rear_wheel_left">
    <material>Gazebo/Black</material>
  </gazebo>

  <gazebo reference="rear_wheel_right">
    <material>Gazebo/Black</material>
  </gazebo>

  <gazebo reference="front_wheel_left">
    <material>Gazebo/Black</material>
  </gazebo>

  <!--Joints-->
  <joint type="continuous" name="joint_front_wheel_left">
    <origin xyz=".15 0.1 0" rpy="0 0 0" />
    <child link="front_wheel_left" />
    <parent link="chassis" />
    <axis xyz="0 1 0" rpy="0 0 0" />
    <limit effort="10000" velocity="1000" />
    <dynamics damping="1.0" friction="1.0" />
  </joint>

  <joint type="continuous" name="joint_front_wheel_right">
    <origin xyz=".15 -0.1 0" rpy="0 0 0" />
    <child link="front_wheel_right" />
    <parent link="chassis" />
    <axis xyz="0 1 0" rpy="0 0 0" />
    <limit effort="10000" velocity="1000" />
    <dynamics damping="1.0" friction="1.0" />
  </joint>

  <joint type="continuous" name="joint_rear_wheel_left">
    <origin xyz="-0.15 0.1 0" rpy="0 0 0" />
    <child link="rear_wheel_left" />
    <parent link="chassis" />
    <axis xyz="0 1 0" rpy="0 0 0" />
    <limit effort="10000" velocity="1000" />
    <dynamics damping="1.0" friction="1.0" />
  </joint>

  <joint type="continuous" name="joint_rear_wheel_right">
    <origin xyz="-0.15 -0.1 0" rpy="0 0 0" />
    <child link="rear_wheel_right" />
    <parent link="chassis" />
    <axis xyz="0 1 0" rpy="0 0 0" />
    <limit effort="10000" velocity="1000" />
    <dynamics damping="1.0" friction="1.0" />
  </joint>

  <joint type="fixed" name="camera_joint">
    <origin xyz="0.22 0 0.07" rpy="0 0 0" />
    <axis xyz="0 1 0" rpy="0 0 0" />
    <parent link="chassis" />
    <child link="camera" />
  </joint>

  <joint name="hokuyo_fixed" type="fixed">
    <origin xyz="0.15 0 0.175" rpy="0 0 0"/>
    <axis xyz="0 1 0" rpy="0 0 0"/>
    <parent link="chassis" />
    <child link="hokuyo" />
  </joint>


</robot>
